# errno.EAGAIN

Try again.

This error is mapped to the exception [`BlockingIOError`](/exceptions/BlockingIOError.md).

### Syntax

```python
errno.EAGAIN
```
